<?xml version="1.0" encoding="utf-8"?>
<mujoco model="go2_with_real_piper_arm">
  <compiler angle="radian" meshdir="assets" autolimits="true" />

  <option cone="elliptic" impratio="100" />

  <default>
    <default class="go2">
      <geom friction="0.4" margin="0.001" condim="1"/>
      <joint axis="0 1 0" damping="0.1" armature="0.01" frictionloss="0.2"/>
      <motor ctrlrange="-23.7 23.7"/>
      <default class="abduction">
        <joint axis="1 0 0" range="-1.0472 1.0472"/>
      </default>
      <default class="hip">
        <default class="front_hip">
          <joint range="-1.5708 3.4907"/>
        </default>
        <default class="back_hip">
          <joint range="-0.5236 4.5379"/>
        </default>
      </default>
      <default class="knee">
        <joint range="-2.7227 -0.83776"/>
        <motor ctrlrange="-45.43 45.43"/>
      </default>
      <default class="visual">
        <geom type="mesh" contype="0" conaffinity="0" group="2"/>
      </default>
      <default class="collision">
        <geom group="3"/>
        <default class="foot">
          <geom size="0.022" pos="-0.002 0 -0.213" priority="1" condim="6"
            friction="0.4 0.02 0.01"/>
        </default>
      </default>
    </default>
    <default class="piper_arm">
      <joint damping="0.5" armature="0.01" frictionloss="0.1"/>
      <motor ctrlrange="-10 10"/>
    </default>
    <default class="motor">
      <joint damping="0.5" armature="0.01" frictionloss="0.1"/>
      <motor ctrlrange="-10 10"/>
    </default>
  </default>

  <asset>
    <!-- Go2 materials -->
    <material name="metal" rgba=".9 .95 .95 1" />
    <material name="black" rgba="0 0 0 1" />
    <material name="white" rgba="1 1 1 1" />
    <material name="gray" rgba="0.671705 0.692426 0.774270 1" />
    
    <!-- Piper arm material -->
    <material name="piper_visual" rgba="0.79 0.82 0.93 1" />
    
    <!-- Go2 meshes -->
    <mesh file="base_0.obj" />
    <mesh file="base_1.obj" />
    <mesh file="base_2.obj" />
    <mesh file="base_3.obj" />
    <mesh file="base_4.obj" />
    <mesh file="hip_0.obj" />
    <mesh file="hip_1.obj" />
    <mesh file="thigh_0.obj" />
    <mesh file="thigh_1.obj" />
    <mesh file="thigh_mirror_0.obj" />
    <mesh file="thigh_mirror_1.obj" />
    <mesh file="calf_0.obj" />
    <mesh file="calf_1.obj" />
    <mesh file="calf_mirror_0.obj" />
    <mesh file="calf_mirror_1.obj" />
    <mesh file="foot.obj" />
    
    <!-- Piper meshes -->
    <mesh name="base_link.STL" file="../piper_meshes/base_link.STL" />
    <mesh name="link1.STL" file="../piper_meshes/link1.STL" />
    <mesh name="link2.STL" file="../piper_meshes/link2.STL" />
    <mesh name="link3.STL" file="../piper_meshes/link3.STL" />
    <mesh name="link4.STL" file="../piper_meshes/link4.STL" />
    <mesh name="link5.STL" file="../piper_meshes/link5.STL" />
    <mesh name="link6.STL" file="../piper_meshes/link6.STL" />
    <mesh name="link7.STL" file="../piper_meshes/link7.STL" />
    <mesh name="link8.STL" file="../piper_meshes/link8.STL" />
  </asset>

  <worldbody>

    <body name="base_link" pos="0 0 0.445" childclass="go2">
      <inertial pos="0.021112 0 -0.005366" quat="-0.000543471 0.713435 -0.00173769 0.700719"
        mass="6.921"
        diaginertia="0.107027 0.0980771 0.0244531" />
      <freejoint />
      <geom mesh="base_0" material="black" class="visual" />
      <geom mesh="base_1" material="black" class="visual" />
      <geom mesh="base_2" material="black" class="visual" />
      <geom mesh="base_3" material="white" class="visual" />
      <geom mesh="base_4" material="gray" class="visual" />
      <geom size="0.1881 0.04675 0.057" type="box" class="collision" />
      <geom size="0.05 0.045" pos="0.285 0 0.01" type="cylinder" class="collision" />
      <geom size="0.047" pos="0.293 0 -0.06" class="collision" />
      <site name="imu" pos="-0.02557 0 0.04232" />
      <body name="FL_hip" pos="0.1934 0.0465 0">
        <inertial pos="-0.0054 0.00194 -0.000105" quat="0.497014 0.499245 0.505462 0.498237"
          mass="0.678"
          diaginertia="0.00088403 0.000596003 0.000479967" />
        <joint name="FL_hip_joint" class="abduction" />
        <geom mesh="hip_0" material="metal" class="visual" />
        <geom mesh="hip_1" material="gray" class="visual" />
        <geom size="0.046 0.02" pos="0 0.08 0" quat="1 1 0 0" type="cylinder" class="collision" />
        <body name="FL_thigh" pos="0 0.0955 0">
          <inertial pos="-0.00374 -0.0223 -0.0327" quat="0.829533 0.0847635 -0.0200632 0.551623"
            mass="1.152"
            diaginertia="0.00594973 0.00584149 0.000878787" />
          <joint name="FL_thigh_joint" class="front_hip" />
          <geom mesh="thigh_0" material="metal" class="visual" />
          <geom mesh="thigh_1" material="gray" class="visual" />
          <geom size="0.1065 0.01225 0.017" pos="0 0 -0.1065" quat="0.707107 0 0.707107 0"
            type="box" class="collision" />
          <body name="FL_calf" pos="0 0 -0.213">
            <inertial pos="0.00629595 -0.000622121 -0.141417"
              quat="0.710672 0.00154099 -0.00450087 0.703508"
              mass="0.241352" diaginertia="0.0014901 0.00146356 5.31397e-05" />
            <joint name="FL_calf_joint" class="knee" />
            <geom mesh="calf_0" material="gray" class="visual" />
            <geom mesh="calf_1" material="black" class="visual" />
            <geom size="0.012 0.06" pos="0.008 0 -0.06" quat="0.994493 0 -0.104807 0"
              type="cylinder" class="collision" />
            <geom size="0.011 0.0325" pos="0.02 0 -0.148" quat="0.999688 0 0.0249974 0"
              type="cylinder" class="collision" />
            <geom pos="0 0 -0.213" mesh="foot" class="visual" material="black" />
            <geom name="FL" class="foot" />
            <body name="FL_foot" pos="0 0 -0.213" />
          </body>
        </body>
      </body>
      <body name="FR_hip" pos="0.1934 -0.0465 0">
        <inertial pos="-0.0054 -0.00194 -0.000105" quat="0.498237 0.505462 0.499245 0.497014"
          mass="0.678"
          diaginertia="0.00088403 0.000596003 0.000479967" />
        <joint name="FR_hip_joint" class="abduction" />
        <geom mesh="hip_0" material="metal" class="visual" quat="4.63268e-05 1 0 0" />
        <geom mesh="hip_1" material="gray" class="visual" quat="4.63268e-05 1 0 0" />
        <geom size="0.046 0.02" pos="0 -0.08 0" quat="0.707107 0.707107 0 0" type="cylinder"
          class="collision" />
        <body name="FR_thigh" pos="0 -0.0955 0">
          <inertial pos="-0.00374 0.0223 -0.0327" quat="0.551623 -0.0200632 0.0847635 0.829533"
            mass="1.152"
            diaginertia="0.00594973 0.00584149 0.000878787" />
          <joint name="FR_thigh_joint" class="front_hip" />
          <geom mesh="thigh_mirror_0" material="metal" class="visual" />
          <geom mesh="thigh_mirror_1" material="gray" class="visual" />
          <geom size="0.1065 0.01225 0.017" pos="0 0 -0.1065" quat="0.707107 0 0.707107 0"
            type="box" class="collision" />
          <body name="FR_calf" pos="0 0 -0.213">
            <inertial pos="0.00629595 0.000622121 -0.141417"
              quat="0.703508 -0.00450087 0.00154099 0.710672"
              mass="0.241352" diaginertia="0.0014901 0.00146356 5.31397e-05" />
            <joint name="FR_calf_joint" class="knee" />
            <geom mesh="calf_mirror_0" material="gray" class="visual" />
            <geom mesh="calf_mirror_1" material="black" class="visual" />
            <geom size="0.013 0.06" pos="0.01 0 -0.06" quat="0.995004 0 -0.0998334 0"
              type="cylinder" class="collision" />
            <geom size="0.011 0.0325" pos="0.02 0 -0.148" quat="0.999688 0 0.0249974 0"
              type="cylinder" class="collision" />
            <geom pos="0 0 -0.213" mesh="foot" class="visual" material="black" />
            <geom name="FR" class="foot" />
            <body name="FR_foot" pos="0 0 -0.213" />
          </body>
        </body>
      </body>
      <body name="RL_hip" pos="-0.1934 0.0465 0">
        <inertial pos="0.0054 0.00194 -0.000105" quat="0.505462 0.498237 0.497014 0.499245"
          mass="0.678"
          diaginertia="0.00088403 0.000596003 0.000479967" />
        <joint name="RL_hip_joint" class="abduction" />
        <geom mesh="hip_0" material="metal" class="visual" quat="4.63268e-05 0 1 0" />
        <geom mesh="hip_1" material="gray" class="visual" quat="4.63268e-05 0 1 0" />
        <geom size="0.046 0.02" pos="0 0.08 0" quat="0.707107 0.707107 0 0" type="cylinder"
          class="collision" />
        <body name="RL_thigh" pos="0 0.0955 0">
          <inertial pos="-0.00374 -0.0223 -0.0327" quat="0.829533 0.0847635 -0.0200632 0.551623"
            mass="1.152"
            diaginertia="0.00594973 0.00584149 0.000878787" />
          <joint name="RL_thigh_joint" class="back_hip" />
          <geom mesh="thigh_0" material="metal" class="visual" />
          <geom mesh="thigh_1" material="gray" class="visual" />
          <geom size="0.1065 0.01225 0.017" pos="0 0 -0.1065" quat="0.707107 0 0.707107 0"
            type="box" class="collision" />
          <body name="RL_calf" pos="0 0 -0.213">
            <inertial pos="0.00629595 -0.000622121 -0.141417"
              quat="0.710672 0.00154099 -0.00450087 0.703508"
              mass="0.241352" diaginertia="0.0014901 0.00146356 5.31397e-05" />
            <joint name="RL_calf_joint" class="knee" />
            <geom mesh="calf_0" material="gray" class="visual" />
            <geom mesh="calf_1" material="black" class="visual" />
            <geom size="0.013 0.06" pos="0.01 0 -0.06" quat="0.995004 0 -0.0998334 0"
              type="cylinder" class="collision" />
            <geom size="0.011 0.0325" pos="0.02 0 -0.148" quat="0.999688 0 0.0249974 0"
              type="cylinder" class="collision" />
            <geom pos="0 0 -0.213" mesh="foot" class="visual" material="black" />
            <geom name="RL" class="foot" />
            <body name="RL_foot" pos="0 0 -0.213" />
          </body>
        </body>
      </body>
      <body name="RR_hip" pos="-0.1934 -0.0465 0">
        <inertial pos="0.0054 -0.00194 -0.000105" quat="0.499245 0.497014 0.498237 0.505462"
          mass="0.678"
          diaginertia="0.00088403 0.000596003 0.000479967" />
        <joint name="RR_hip_joint" class="abduction" />
        <geom mesh="hip_0" material="metal" class="visual"
          quat="2.14617e-09 4.63268e-05 4.63268e-05 -1" />
        <geom mesh="hip_1" material="gray" class="visual"
          quat="2.14617e-09 4.63268e-05 4.63268e-05 -1" />
        <geom size="0.046 0.02" pos="0 -0.08 0" quat="0.707107 0.707107 0 0" type="cylinder"
          class="collision" />
        <body name="RR_thigh" pos="0 -0.0955 0">
          <inertial pos="-0.00374 0.0223 -0.0327" quat="0.551623 -0.0200632 0.0847635 0.829533"
            mass="1.152"
            diaginertia="0.00594973 0.00584149 0.000878787" />
          <joint name="RR_thigh_joint" class="back_hip" />
          <geom mesh="thigh_mirror_0" material="metal" class="visual" />
          <geom mesh="thigh_mirror_1" material="gray" class="visual" />
          <geom size="0.1065 0.01225 0.017" pos="0 0 -0.1065" quat="0.707107 0 0.707107 0"
            type="box" class="collision" />
          <body name="RR_calf" pos="0 0 -0.213">
            <inertial pos="0.00629595 0.000622121 -0.141417"
              quat="0.703508 -0.00450087 0.00154099 0.710672"
              mass="0.241352" diaginertia="0.0014901 0.00146356 5.31397e-05" />
            <joint name="RR_calf_joint" class="knee" />
            <geom mesh="calf_mirror_0" material="gray" class="visual" />
            <geom mesh="calf_mirror_1" material="black" class="visual" />
            <geom size="0.013 0.06" pos="0.01 0 -0.06" quat="0.995004 0 -0.0998334 0"
              type="cylinder" class="collision" />
            <geom size="0.011 0.0325" pos="0.02 0 -0.148" quat="0.999688 0 0.0249974 0"
              type="cylinder" class="collision" />
            <geom pos="0 0 -0.213" mesh="foot" class="visual" material="black" />
            <geom name="RR" class="foot" />
            <body name="RR_foot" pos="0 0 -0.213" />
          </body>
        </body>
      </body>
    
      
      <geom name="base_link_collision" pos="0 0 0" quat="1.0 0.0 0.0 0.0" type="mesh" mesh="base_link.STL" class="collision" />
      <geom name="base_link_visual" pos="0 0 0" quat="1.0 0.0 0.0 0.0" material="piper_visual" type="mesh" mesh="base_link.STL" class="visual" />
      <body name="link1" pos="0 0 0.123" quat="0.7071054825112363 0.0 0.0 -0.7071080798594735">
        <joint name="arm_joint1" type="hinge" ref="0.0" class="motor" range="-2.618 2.618" axis="0 0 1" />>
        <inertial pos="0.00131676031927021 0.000310288842008364 -0.00922874512303438" quat="1.0 0.0 0.0 0.0" mass="0.0978679932242825" diaginertia="7.76684558296781e-05 9.24967780161546e-05 8.24589062407806e-05" />
        <geom name="link1_collision" pos="0 0 0" quat="1.0 0.0 0.0 0.0" type="mesh" mesh="link1.STL" class="collision" />
        <geom name="link1_visual" pos="0 0 0" quat="1.0 0.0 0.0 0.0" material="piper_visual" type="mesh" mesh="link1.STL" class="visual" />
        <body name="link2" pos="0 0 0" quat="0.5245882472032842 0.4741364188121476 -0.5245917304039108 -0.4741364188121475">
          <joint name="arm_joint2" type="hinge" ref="0.0" class="motor" range="0 3.14" axis="0 0 1" />>
          <inertial pos="0.147615838821413 -0.0174259998251393 0.00175952516190707" quat="1.0 0.0 0.0 0.0" mass="0.289571136953082" diaginertia="0.000150112628108228 0.00172585302855383 0.00177445942914759" />
          <geom name="link2_collision" pos="0 0 0" quat="1.0 0.0 0.0 0.0" type="mesh" mesh="link2.STL" class="collision" />
          <geom name="link2_visual" pos="0 0 0" quat="1.0 0.0 0.0 0.0" material="piper_visual" type="mesh" mesh="link2.STL" class="visual" />
          <body name="link3" pos="0.28503 0 0" quat="0.7704178651905058 0.0 0.0 0.6375392638852164">
            <joint name="arm_joint3" type="hinge" ref="0.0" class="motor" range="-2.967 0" axis="0 0 1" />>
            <inertial pos="0.0156727246030052 0.104466514905741 0.000508486764144372" quat="1.0 0.0 0.0 0.0" mass="0.290583247455324" diaginertia="0.000221686352136266 0.000100859162015934 0.000241839316548946" />
            <geom name="link3_collision" pos="0 0 0" quat="1.0 0.0 0.0 0.0" type="mesh" mesh="link3.STL" class="collision" />
            <geom name="link3_visual" pos="0 0 0" quat="1.0 0.0 0.0 0.0" material="piper_visual" type="mesh" mesh="link3.STL" class="visual" />
            <body name="link4" pos="0.021984 0.25075 0" quat="0.7071054825112363 -0.7071080798594735 0.0 0.0">
              <joint name="arm_joint4" type="hinge" ref="0.0" class="motor" range="-1.832 1.832" axis="0 0 -1" />>
              <inertial pos="0.000276464622388145 -0.00102803669324853 -0.00472830700561612" quat="1.0 0.0 0.0 0.0" mass="0.127087348341362" diaginertia="3.82011730423098e-05 4.87048555222491e-05 4.10592077565155e-05" />
              <geom name="link4_collision" pos="0 0 0" quat="1.0 0.0 0.0 0.0" type="mesh" mesh="link4.STL" class="collision" />
              <geom name="link4_visual" pos="0 0 0" quat="1.0 0.0 0.0 0.0" material="piper_visual" type="mesh" mesh="link4.STL" class="visual" />
              <body name="link5" pos="0 0 0" quat="0.7064324819077121 0.7064350767838756 -0.030843344552078336 0.030843457846217025">
                <joint name="arm_joint5" type="hinge" ref="0.0" class="motor" range="-1.22 1.22" axis="0 0 1" />>
                <inertial pos="8.82261259100015E-05 0.056682908434204 -0.00196119077436732" quat="1.0 0.0 0.0 0.0" mass="0.144711209371719" diaginertia="4.39644269159173e-05 5.63173857792457e-05 4.88713595021005e-05" />
                <geom name="link5_collision" pos="0 0 0" quat="1.0 0.0 0.0 0.0" type="mesh" mesh="link5.STL" class="collision" />
                <geom name="link5_visual" pos="0 0 0" quat="1.0 0.0 0.0 0.0" material="piper_visual" type="mesh" mesh="link5.STL" class="visual" />
                <body name="link6" pos="0 0.091 0.0014165" quat="0.4999981633974483 -0.49999999999662686 -0.49999999999662686 -0.5000018366025516">
                  <joint name="arm_joint6" type="hinge" ref="0.0" class="motor" range="-3.14 3.14" axis="0 0 -1" />>
                  <inertial pos="9.41121070072333E-09 0.000341209775988838 0.0342122921883722" quat="1.0 0.0 0.0 0.0" mass="0.150196458571266" diaginertia="4.31750564711759e-05 9.99756357365307e-05 0.000118282295533688" />
                  <geom name="link6_collision" pos="0 0 0" quat="1.0 0.0 0.0 0.0" type="mesh" mesh="link6.STL" class="collision" />
                  <geom name="link6_visual" pos="0 0 0" quat="1.0 0.0 0.0 0.0" material="piper_visual" type="mesh" mesh="link6.STL" class="visual" />
                  <body name="link7" pos="0 0 0.13503" quat="0.4999981633974483 0.49999999999662686 0.5000018366025516 0.49999999999662686">
                    <joint name="arm_joint7" type="slide" ref="0.0" class="motor" range="-0.038 0" axis="0 0 -1" />>
                    <inertial pos="-0.000277795893713934 -0.046767350270289 -0.00921029791141448" quat="1.0 0.0 0.0 0.0" mass="0.0264822500394006" diaginertia="9.99782519244544e-06 6.17952364356547e-06 1.42102253390315e-05" />
                    <geom name="link7_collision" pos="0 0 0" quat="1.0 0.0 0.0 0.0" type="mesh" mesh="link7.STL" class="collision" />
                    <geom name="link7_visual" pos="0 0 0" quat="1.0 0.0 0.0 0.0" material="piper_visual" type="mesh" mesh="link7.STL" class="visual" />
                  </body>
                  <body name="link8" pos="0 0 0.13503" quat="0.4999981633974483 -0.49999999999662686 -0.5000018366025516 0.49999999999662686">
                    <joint name="arm_joint8" type="slide" ref="0.0" class="motor" range="0 0.038" axis="0 0 1" />>
                    <inertial pos="0.000277795911672651 0.0467673513153836 -0.00921029799058583" quat="1.0 0.0 0.0 0.0" mass="0.0264822490707451" diaginertia="9.99782474142963e-06 6.17952362333486e-06 1.42102248648757e-05" />
                    <geom name="link8_collision" pos="0 0 0" quat="1.0 0.0 0.0 0.0" type="mesh" mesh="link8.STL" class="collision" />
                    <geom name="link8_visual" pos="0 0 0" quat="1.0 0.0 0.0 0.0" material="piper_visual" type="mesh" mesh="link8.STL" class="visual" />
                  </body>
                </body>
              </body>
            </body>
          </body>
        </body>
      </body>
      <site name="base_link_site" pos="0 0 0" quat="1 0 0 0" />
      <camera name="front_camera" mode="track" fovy="90.0" quat="4.329780281177467e-17 4.329780281177466e-17 0.7071067811865475 0.7071067811865476" pos="0.0 2.0 0.5" />
      <camera name="side_camera" mode="track" fovy="90.0" quat="-0.5 -0.4999999999999999 0.5 0.5000000000000001" pos="-2.0 0.0 0.5" />
    </body>
  
  </worldbody>

  <actuator>

    <motor class="abduction" name="FR_hip" joint="FR_hip_joint" />
    <motor class="hip" name="FR_thigh" joint="FR_thigh_joint" />
    <motor class="knee" name="FR_calf" joint="FR_calf_joint" />
    <motor class="abduction" name="FL_hip" joint="FL_hip_joint" />
    <motor class="hip" name="FL_thigh" joint="FL_thigh_joint" />
    <motor class="knee" name="FL_calf" joint="FL_calf_joint" />
    <motor class="abduction" name="RR_hip" joint="RR_hip_joint" />
    <motor class="hip" name="RR_thigh" joint="RR_thigh_joint" />
    <motor class="knee" name="RR_calf" joint="RR_calf_joint" />
    <motor class="abduction" name="RL_hip" joint="RL_hip_joint" />
    <motor class="hip" name="RL_thigh" joint="RL_thigh_joint" />
    <motor class="knee" name="RL_calf" joint="RL_calf_joint" />
  
    <motor name="arm_motor1" joint="arm_joint1" class="motor" />
    <motor name="arm_motor2" joint="arm_joint2" class="motor" />
    <motor name="arm_motor3" joint="arm_joint3" class="motor" />
    <motor name="arm_motor4" joint="arm_joint4" class="motor" />
    <motor name="arm_motor5" joint="arm_joint5" class="motor" />
    <motor name="arm_motor6" joint="arm_joint6" class="motor" />
    <motor name="arm_motor7" joint="arm_joint7" class="motor" />
    <motor name="arm_motor8" joint="arm_joint8" class="motor" />
  
  </actuator>

  <sensor>

    <jointpos name="FR_hip_pos" joint="FR_hip_joint" />
    <jointpos name="FR_thigh_pos" joint="FR_thigh_joint" />
    <jointpos name="FR_calf_pos" joint="FR_calf_joint" />
    <jointpos name="FL_hip_pos" joint="FL_hip_joint" />
    <jointpos name="FL_thigh_pos" joint="FL_thigh_joint" />
    <jointpos name="FL_calf_pos" joint="FL_calf_joint" />
    <jointpos name="RR_hip_pos" joint="RR_hip_joint" />
    <jointpos name="RR_thigh_pos" joint="RR_thigh_joint" />
    <jointpos name="RR_calf_pos" joint="RR_calf_joint" />
    <jointpos name="RL_hip_pos" joint="RL_hip_joint" />
    <jointpos name="RL_thigh_pos" joint="RL_thigh_joint" />
    <jointpos name="RL_calf_pos" joint="RL_calf_joint" />

    <jointvel name="FR_hip_vel" joint="FR_hip_joint" />
    <jointvel name="FR_thigh_vel" joint="FR_thigh_joint" />
    <jointvel name="FR_calf_vel" joint="FR_calf_joint" />
    <jointvel name="FL_hip_vel" joint="FL_hip_joint" />
    <jointvel name="FL_thigh_vel" joint="FL_thigh_joint" />
    <jointvel name="FL_calf_vel" joint="FL_calf_joint" />
    <jointvel name="RR_hip_vel" joint="RR_hip_joint" />
    <jointvel name="RR_thigh_vel" joint="RR_thigh_joint" />
    <jointvel name="RR_calf_vel" joint="RR_calf_joint" />
    <jointvel name="RL_hip_vel" joint="RL_hip_joint" />
    <jointvel name="RL_thigh_vel" joint="RL_thigh_joint" />
    <jointvel name="RL_calf_vel" joint="RL_calf_joint" />

    <jointactuatorfrc name="FR_hip_torque" joint="FR_hip_joint" noise="0.01" />
    <jointactuatorfrc name="FR_thigh_torque" joint="FR_thigh_joint" noise="0.01" />
    <jointactuatorfrc name="FR_calf_torque" joint="FR_calf_joint" noise="0.01" />
    <jointactuatorfrc name="FL_hip_torque" joint="FL_hip_joint" noise="0.01" />
    <jointactuatorfrc name="FL_thigh_torque" joint="FL_thigh_joint" noise="0.01" />
    <jointactuatorfrc name="FL_calf_torque" joint="FL_calf_joint" noise="0.01" />
    <jointactuatorfrc name="RR_hip_torque" joint="RR_hip_joint" noise="0.01" />
    <jointactuatorfrc name="RR_thigh_torque" joint="RR_thigh_joint" noise="0.01" />
    <jointactuatorfrc name="RR_calf_torque" joint="RR_calf_joint" noise="0.01" />
    <jointactuatorfrc name="RL_hip_torque" joint="RL_hip_joint" noise="0.01" />
    <jointactuatorfrc name="RL_thigh_torque" joint="RL_thigh_joint" noise="0.01" />
    <jointactuatorfrc name="RL_calf_torque" joint="RL_calf_joint" noise="0.01" />

    <framequat name="imu_quat" objtype="site" objname="imu" />
    <gyro name="imu_gyro" site="imu" />
    <accelerometer name="imu_acc" site="imu" />
    
    <framepos name="frame_pos" objtype="site" objname="imu" />
    <framelinvel name="frame_vel" objtype="site" objname="imu" />
  
    <framepos name="base_link_site_pos" objtype="site" objname="base_link_site" />
    <framequat name="base_link_site_quat" objtype="site" objname="base_link_site" />
    <framelinvel name="base_link_site_linvel" objtype="site" objname="base_link_site" />
    <frameangvel name="base_link_site_angvel" objtype="site" objname="base_link_site" />
    <velocimeter name="base_link_site_vel" site="base_link_site" />
  
  </sensor>
</mujoco>
